{
 "cells": [
  {
   "cell_type": "code",
   "execution_count": null,
   "id": "15c37093-ce3a-44c8-880e-4110b814342d",
   "metadata": {},
   "outputs": [],
   "source": [
    "1. What is an Exception in python ? write the difference between exception and syntax errors.\n",
    "ans= An exception is an event, which occurs during the execution of a program that disrupts the normal flow of the program's instructions.\n",
    "while syntax error are the Errors mostly happen at compile-time; however it can happen at runtime as well. Whereas an Exception occurs at runtime."
   ]
  },
  {
   "cell_type": "code",
   "execution_count": null,
   "id": "bc9cfd35-ff2c-4f59-a87b-6a1eb04ec5a2",
   "metadata": {},
   "outputs": [],
   "source": [
    "2. What happens when an exception is not handlede ?\n",
    "explain with an example.\n",
    "ANS===\n",
    "When an exception is not handled in a program, it leads to what is commonly known as an \"unhandled exception.\" This means that the program encounters an error or exceptional condition, but there is no specific code to deal with that error, resulting in the termination of the program abruptly. The program \"crashes\" or throws a runtime error, and the stack trace is usually displayed, showing the sequence of function calls that led to the unhandled exception.\n",
    "\n",
    "CODE= \n",
    "def divide_numbers(a, b):\n",
    "    result = a / b\n",
    "    return result\n",
    "\n",
    "def main():\n",
    "    try:\n",
    "        num1 = int(input(\"Enter the first number: \"))\n",
    "        num2 = int(input(\"Enter the second number: \"))\n",
    "        result = divide_numbers(num1, num2)\n",
    "        print(\"Result: \", result)\n",
    "    except ValueError:\n",
    "        print(\"Invalid input. Please enter valid integers.\")\n",
    "    finally:\n",
    "        print(\"This block will always execute.\")\n",
    "\n",
    "if __name__ == \"__main__\":\n",
    "    main()\n"
   ]
  },
  {
   "cell_type": "code",
   "execution_count": null,
   "id": "692f5eb7-b61f-4b2c-975f-fcca3eca849d",
   "metadata": {},
   "outputs": [],
   "source": [
    "3. WHICH PYTHON STATEMENT ARE USED TO CATCH AND HANDLE EXCEPTIONS ? EXPLAIN WITH AN EXAMPLE.\n",
    "ANS = \n",
    "TRY AND EXCEPTION STATEMENT ARE USED TO CATCH AND HANDLE EXCEPTIONS \n",
    "CODE= try:\n",
    "    # Code that may raise an exception\n",
    "except SomeExceptionType:\n",
    "    # Code to handle the exception if it occurs\n",
    "finally:\n",
    "    # Optional block that will always execute, regardless of whether an exception occurred or not\n"
   ]
  },
  {
   "cell_type": "code",
   "execution_count": null,
   "id": "a9839c7d-9614-4363-9eeb-8af05a9cf47d",
   "metadata": {},
   "outputs": [],
   "source": [
    "4. EXPLAIN WITH EXAMPLE :- TRY AND ELSE\n",
    "FINALLY\n",
    "RAISE\n",
    "ANS== \n",
    "Certainly! Let's explain the concepts of try, else, finally, and raise in Python with examples.\n",
    "\n",
    "try, except, and else:\n",
    "The try, except, and else blocks are used together for handling exceptions in Python. The try block contains the code that may raise an exception, and the except block catches and handles the exception. The else block is optional and gets executed if no exception is raised in the try block. It is typically used for code that should run when no exceptions occur.\n",
    "Example:\n",
    "\n",
    "python\n",
    "Copy code\n",
    "def divide_numbers(a, b):\n",
    "    try:\n",
    "        result = a / b\n",
    "    except ZeroDivisionError:\n",
    "        print(\"Error: Division by zero is not allowed.\")\n",
    "    else:\n",
    "        print(\"Division successful. Result:\", result)\n",
    "\n",
    "divide_numbers(10, 2)  # Output: Division successful. Result: 5.0\n",
    "divide_numbers(10, 0)  # Output: Error: Division by zero is not allowed.\n",
    "In this example, the divide_numbers function attempts to divide a by b. If the division is successful, the else block will be executed, displaying the result. However, if the divisor b is zero, the ZeroDivisionError is caught in the except block, and an error message is printed.\n",
    "\n",
    "finally:\n",
    "The finally block is used to specify a set of statements that will always execute, regardless of whether an exception occurs or not. It is commonly used for cleanup tasks like closing files or releasing resources that need to be done no matter what.\n",
    "Example:\n",
    "\n",
    "python\n",
    "Copy code\n",
    "def divide_numbers(a, b):\n",
    "    try:\n",
    "        result = a / b\n",
    "        return result\n",
    "    except ZeroDivisionError:\n",
    "        print(\"Error: Division by zero is not allowed.\")\n",
    "        return None\n",
    "    finally:\n",
    "        print(\"Division process complete.\")\n",
    "\n",
    "result1 = divide_numbers(10, 2)  # Output: Division process complete.\n",
    "result2 = divide_numbers(10, 0)  # Output: Error: Division by zero is not allowed. Division process complete.\n",
    "In this example, the finally block ensures that the message \"Division process complete\" is always displayed, whether the division is successful or not.\n",
    "\n",
    "raise:\n",
    "The raise statement is used to manually raise exceptions in Python. It allows you to create custom exceptions or re-raise caught exceptions to be handled at a higher level.\n",
    "Example:\n",
    "\n",
    "python\n",
    "Copy code\n",
    "def divide_numbers(a, b):\n",
    "    if b == 0:\n",
    "        raise ValueError(\"Cannot divide by zero.\")\n",
    "    return a / b\n",
    "\n",
    "try:\n",
    "    result = divide_numbers(10, 0)\n",
    "except ValueError as e:\n",
    "    print(\"Error:\", str(e))  # Output: Error: Cannot divide by zero.\n",
    "In this example, we raise a ValueError with a custom error message when the divisor b is zero. The try block catches this custom exception, and we can handle it accordingly.\n",
    "\n",
    "Overall, these constructs (try, except, else, finally, and raise) provide a powerful way to handle exceptions, control the flow of a program, and ensure proper cleanup of resources.\n",
    "\n",
    "\n",
    "\n",
    "\n"
   ]
  },
  {
   "cell_type": "code",
   "execution_count": null,
   "id": "4e493f07-0c8f-4f08-b4de-353e45718017",
   "metadata": {},
   "outputs": [],
   "source": [
    "5. What are Custom Exceptions in python?\n",
    "ans==\n",
    "Custom Exceptions in Python are user-defined exception classes that allow developers to create their own specific types of exceptions. These custom exception classes are derived from the base Exception class or its subclasses.\n",
    "code== \n",
    "\n",
    "class CustomError(Exception):\n",
    "    def __init__(self, message):\n",
    "        self.message = message\n",
    "\n",
    "    def __str__(self):\n",
    "        return f\"CustomError: {self.message}\"\n",
    "\n",
    "def process_data(data):\n",
    "    if not isinstance(data, int):\n",
    "        raise CustomError(\"Invalid data type. Expected an integer.\")\n",
    "    # Some data processing code here...\n",
    "\n",
    "try:\n",
    "    input_data = input(\"Enter an integer: \")\n",
    "    input_data = int(input_data)\n",
    "    process_data(input_data)\n",
    "except CustomError as ce:\n",
    "    print(ce)\n"
   ]
  },
  {
   "cell_type": "code",
   "execution_count": null,
   "id": "1a2efdce-2d13-4a1a-b33f-72175dfc9d60",
   "metadata": {},
   "outputs": [],
   "source": []
  }
 ],
 "metadata": {
  "kernelspec": {
   "display_name": "Python 3 (ipykernel)",
   "language": "python",
   "name": "python3"
  },
  "language_info": {
   "codemirror_mode": {
    "name": "ipython",
    "version": 3
   },
   "file_extension": ".py",
   "mimetype": "text/x-python",
   "name": "python",
   "nbconvert_exporter": "python",
   "pygments_lexer": "ipython3",
   "version": "3.10.8"
  }
 },
 "nbformat": 4,
 "nbformat_minor": 5
}
